Workbook

Sheet Start Here
A1: AAJ
A2: Pricing Page Teardown & Price-Test Log
A3: Find what your pricing page makes hard. Then test a price only when your traffic can answer the question.
B5: Why this workbook
B6: Most pricing pages I review have the same two problems. The first is that the page makes the buyer do the work: decode the value metric, guess what they would actually pay, hunt for how to cancel. The second shows up when the team wants to change the price. They run a test their traffic cannot answer, stop it the week it looks good, and ship a guess with a p-value attached.
B7: This workbook deals with both. The teardown scores your pricing page, and up to three competitors', against 21 checks in about an hour, and tells you what to fix first. The test plan tells you before you start whether a live price test can give you an answer at all, and what to do instead when it cannot. The log keeps every price test honest: the plan is written before launch, and the read-out is against it.
B9: The AAJ method, applied to pricing pages
B10: Stage | C10: Tabs | D10: What it does
B11: Diagnose | C11: Teardown · Competitor Grid | D11: Score your page and three competitors on the same 21 checks, record the facts of each price list, and get the five fixes that matter most.
B12: Design | C12: Test Plan | D12: Work out the break-even conversion for a new price, how many visitors a fair test needs, and whether you have them. Write the decision rules before launch.
B13: Execute | C13: Test Log | D13: Record every price test, before-and-after change and sales-quote trial against its plan. The read-out says whether the planned size was reached and what the numbers support.
B15: How to use it, in order
B16: 1. Teardown: name up to three competitors in row 8, then answer every check for your page and theirs. Say “Not sure” rather than guessing; it is scored as a miss and counted separately.
B17: 2. Competitor Grid: record the facts of each price list with the date you captured them. Pricing pages change, so the date matters.
B18: 3. Fix the page first. Most of the Teardown's fixes need no test at all.
B19: 4. Test Plan: before changing a price, fill in section 2 and read the verdict. If a live test cannot answer the question in the time you have, use one of the alternatives in section 5.
B20: 5. Write the decision rules in section 4 before launch, while nobody is invested in the answer.
B21: 6. Test Log: one row per test. Enter the planned size before launch and the results at the end. Put a retention check in the diary, because a price that sells can still churn.
B23: Reading the cells
B24: Fill me in | C24: Yellow fill, blue text: you type here or pick from the dropdown.
B25: Auto | C25: Bold navy text: a formula. It recalculates from your inputs. Do not type over it.
B26: Worked example | C26: Every tab is pre-filled with one example carried through: Fieldnote, a scheduling app for small field-service businesses, testing a price rise on its Team plan. Fieldnote is invented, and so are its competitors (A, B and C) and every number. Replace them with yours.
B28: The rules on disclosure, cancellation and price comparisons are summarised from the sources on the last tab, as of September 2026. I am not a lawyer, and this is where to start, not legal advice. Rules differ by country and state, and some apply to consumers only.
B30: AAJ · aajconsult.com · Saroj Jha · saroj@aajconsult.com

Sheet Diagnose - Teardown
A1: AAJ
A2: Diagnose — Pricing Page Teardown
A3: Score your page and up to three competitors on the same checks. Weights are my judgement of what costs a buyer most, not a benchmark.
B5: Answer each check Yes, Partly, No or Not sure. Yes scores 2 points, Partly 1, No and Not sure 0, each multiplied by the weight. Unanswered checks are left out of the score. Judge what a buyer sees today, not what is planned.
B7: # | C7: Area | D7: Check | E7: Why it matters | F7: Weight | G7: Your page | H7: What you saw (evidence) | I7: Competitor 1 | J7: Competitor 2 | K7: Competitor 3 | M7: Fix priority (auto) | N7: Rank key (auto) | O7: Competitors that pass (auto)
D8: Names → | G8: Fieldnote | I8: Competitor A | J8: Competitor B | K8: Competitor C
B9: 1 | C9: Clarity | D9: Each plan says who it is for, in words that buyer would use. | E9: Buyers choose a plan by recognising themselves in it, not by comparing feature lists. | F9: 3 | G9: Partly | H9: Plan names say Starter/Team/Business; only Team says who it is for. | I9: Yes | J9: No | K9: Partly | M9: =IF(G9="","",F9*(2-IF(G9="Yes",2,IF(G9="Partly",1,0)))) -> 3 | N9: =IF(M9="",-1,M9+(29+1-ROW())/1000) -> 3.021 | O9: =COUNTIF(I9:K9,"Yes") -> 1
B10: 2 | C10: Clarity | D10: A buyer can tell roughly what they would pay: a price, or for “Contact sales”, what drives the price and where it starts. | E10: An unanswered price question sends the buyer to a competitor or to a sales call they did not want yet. | F10: 3 | G10: Yes | H10: All three self-serve prices shown; Business says “from $149”. | I10: Yes | J10: Partly | K10: No | M10: =IF(G10="","",F10*(2-IF(G10="Yes",2,IF(G10="Partly",1,0)))) -> 0 | N10: =IF(M10="",-1,M10+(29+1-ROW())/1000) -> 0.02 | O10: =COUNTIF(I10:K10,"Yes") -> 1
B11: 3 | C11: Clarity | D11: The value metric (per seat, per job, per account) is named, and it grows with the value the customer gets. | E11: If the bill grows faster than the value, the customer notices at renewal. | F11: 3 | G11: Partly | H11: Per technician, but dispatchers are counted as seats too. | I11: Yes | J11: Yes | K11: Partly | M11: =IF(G11="","",F11*(2-IF(G11="Yes",2,IF(G11="Partly",1,0)))) -> 3 | N11: =IF(M11="",-1,M11+(29+1-ROW())/1000) -> 3.019 | O11: =COUNTIF(I11:K11,"Yes") -> 2
B12: 4 | C12: Clarity | D12: Billing is plain: monthly or annual, what is charged today, the currency, and whether tax is extra. | E12: Surprises at checkout are where committed buyers turn back. | F12: 2 | G12: No | H12: Tax not mentioned; annual toggle shows per-month price with no “billed annually”. | I12: Yes | J12: Partly | K12: Yes | M12: =IF(G12="","",F12*(2-IF(G12="Yes",2,IF(G12="Partly",1,0)))) -> 4 | N12: =IF(M12="",-1,M12+(29+1-ROW())/1000) -> 4.018 | O12: =COUNTIF(I12:K12,"Yes") -> 2
B13: 5 | C13: Clarity | D13: Plan differences are shown as limits and outcomes a buyer cares about, not a wall of ticks. | E13: A long comparison table hides the two or three differences that actually decide the choice. | F13: 2 | G13: No | H13: 42-row tick table; the three real differences are rows 3, 17 and 30. | I13: Partly | J13: No | K13: Partly | M13: =IF(G13="","",F13*(2-IF(G13="Yes",2,IF(G13="Partly",1,0)))) -> 4 | N13: =IF(M13="",-1,M13+(29+1-ROW())/1000) -> 4.017 | O13: =COUNTIF(I13:K13,"Yes") -> 0
B14: 6 | C14: Choice | D14: Every plan exists for a distinct buyer; there are no two plans a buyer cannot tell apart. | E14: A plan nobody can place in their head is a plan that makes the whole page harder. | F14: 2 | G14: Yes | I14: Yes | J14: Partly | K14: Yes | M14: =IF(G14="","",F14*(2-IF(G14="Yes",2,IF(G14="Partly",1,0)))) -> 0 | N14: =IF(M14="",-1,M14+(29+1-ROW())/1000) -> 0.016 | O14: =COUNTIF(I14:K14,"Yes") -> 2
B15: 7 | C15: Choice | D15: One plan is marked as the usual choice, and the page says why. | E15: A recommendation with a reason is advice. Without the reason it reads as a sales push. | F15: 1 | G15: Partly | H15: “Most popular” badge on Team, no reason given. | I15: Yes | J15: Yes | K15: No | M15: =IF(G15="","",F15*(2-IF(G15="Yes",2,IF(G15="Partly",1,0)))) -> 1 | N15: =IF(M15="",-1,M15+(29+1-ROW())/1000) -> 1.015 | O15: =COUNTIF(I15:K15,"Yes") -> 2
B16: 8 | C16: Choice | D16: It is clear what happens at each limit: an overage charge, an upgrade, or a hard stop. | E16: Buyers who cannot see the ceiling assume the worst about it. | F16: 2 | G16: No | H16: Job limit on Starter is not stated anywhere on the page. | I16: Partly | J16: No | K16: Yes | M16: =IF(G16="","",F16*(2-IF(G16="Yes",2,IF(G16="Partly",1,0)))) -> 4 | N16: =IF(M16="",-1,M16+(29+1-ROW())/1000) -> 4.014 | O16: =COUNTIF(I16:K16,"Yes") -> 1
B17: 9 | C17: Choice | D17: The way in matches how people buy (free plan, trial, demo or pilot), and the page says which. | E17: A trial offered to buyers who need a demo, or the reverse, loses both. | F17: 2 | G17: Yes | H17: 14-day trial, no card. | I17: Yes | J17: Yes | K17: Partly | M17: =IF(G17="","",F17*(2-IF(G17="Yes",2,IF(G17="Partly",1,0)))) -> 0 | N17: =IF(M17="",-1,M17+(29+1-ROW())/1000) -> 0.013 | O17: =COUNTIF(I17:K17,"Yes") -> 2
B18: 10 | C18: Proof & risk | D18: Proof sits near the price and speaks to that plan’s buyer: a result or quote used with written permission. | E18: Proof about a different kind of customer does not reduce this buyer’s risk. | F18: 2 | G18: No | H18: Quotes are on the homepage only. | I18: Yes | J18: Partly | K18: No | M18: =IF(G18="","",F18*(2-IF(G18="Yes",2,IF(G18="Partly",1,0)))) -> 4 | N18: =IF(M18="",-1,M18+(29+1-ROW())/1000) -> 4.012 | O18: =COUNTIF(I18:K18,"Yes") -> 1
B19: 11 | C19: Proof & risk | D19: Risk reducers are stated as actually offered: trial length, what happens when it ends, refunds, cancellation. | E19: Buyers weigh what they could lose. Say it before they have to ask. | F19: 2 | G19: Partly | H19: Trial length stated; what happens at the end is not. | I19: Yes | J19: Partly | K19: Not sure | M19: =IF(G19="","",F19*(2-IF(G19="Yes",2,IF(G19="Partly",1,0)))) -> 2 | N19: =IF(M19="",-1,M19+(29+1-ROW())/1000) -> 2.011 | O19: =COUNTIF(I19:K19,"Yes") -> 1
B20: 12 | C20: Proof & risk | D20: The FAQ answers the price questions sales hears most often. | E20: Every question the page answers is one the buyer does not have to leave the page to ask. | F20: 2 | G20: Partly | H20: FAQ covers payment methods, not seat counting, which sales hears weekly. | I20: Partly | J20: No | K20: Yes | M20: =IF(G20="","",F20*(2-IF(G20="Yes",2,IF(G20="Partly",1,0)))) -> 2 | N20: =IF(M20="",-1,M20+(29+1-ROW())/1000) -> 2.01 | O20: =COUNTIF(I20:K20,"Yes") -> 1
B21: 13 | C21: Proof & risk | D21: Security, compliance and procurement details are one click away for plans sold to companies. | E21: A company buyer often has to satisfy someone else before they can say yes. | F21: 1 | G21: Not sure | I21: Yes | J21: Partly | K21: No | M21: =IF(G21="","",F21*(2-IF(G21="Yes",2,IF(G21="Partly",1,0)))) -> 2 | N21: =IF(M21="",-1,M21+(29+1-ROW())/1000) -> 2.009 | O21: =COUNTIF(I21:K21,"Yes") -> 1
B22: 14 | C22: Friction | D22: Each plan has one next step that fits it (start now, or talk to sales), with no competing buttons. | E22: Two buttons on one plan split the decision the page just helped the buyer make. | F22: 2 | G22: Yes | I22: Yes | J22: Partly | K22: Yes | M22: =IF(G22="","",F22*(2-IF(G22="Yes",2,IF(G22="Partly",1,0)))) -> 0 | N22: =IF(M22="",-1,M22+(29+1-ROW())/1000) -> 0.008 | O22: =COUNTIF(I22:K22,"Yes") -> 2
B23: 15 | C23: Friction | D23: The monthly/annual switch compares like with like and shows the saving honestly. | E23: A saving that only appears after mental arithmetic is not a saving the buyer sees. | F23: 2 | G23: No | H23: Toggle defaults to annual; the monthly price appears only after switching. | I23: Yes | J23: Partly | K23: Partly | M23: =IF(G23="","",F23*(2-IF(G23="Yes",2,IF(G23="Partly",1,0)))) -> 4 | N23: =IF(M23="",-1,M23+(29+1-ROW())/1000) -> 4.007 | O23: =COUNTIF(I23:K23,"Yes") -> 1
B24: 16 | C24: Friction | D24: On a phone, every plan and price can be read without sideways scrolling. | E24: A pricing table built for a wide screen can hide the right-hand plan on a phone. | F24: 1 | G24: Partly | H24: Business column cut off at phone width. | I24: Yes | J24: No | K24: Yes | M24: =IF(G24="","",F24*(2-IF(G24="Yes",2,IF(G24="Partly",1,0)))) -> 1 | N24: =IF(M24="",-1,M24+(29+1-ROW())/1000) -> 1.006 | O24: =COUNTIF(I24:K24,"Yes") -> 2
B25: 17 | C25: Friction | D25: The price and terms at checkout match the pricing page exactly. | E25: A mismatch at checkout breaks trust at the moment the buyer is about to pay. | F25: 3 | G25: Yes | H25: Checked by starting a trial on 2 September. | I25: Yes | J25: Not sure | K25: Yes | M25: =IF(G25="","",F25*(2-IF(G25="Yes",2,IF(G25="Partly",1,0)))) -> 0 | N25: =IF(M25="",-1,M25+(29+1-ROW())/1000) -> 0.005 | O25: =COUNTIF(I25:K25,"Yes") -> 2
B26: 18 | C26: Honesty & terms | D26: For subscriptions: price, billing frequency, renewal and how to cancel are disclosed before billing details are asked for. | E26: In the US, ROSCA requires clear and conspicuous disclosure of all material terms before billing information is obtained. See Sources. | F26: 3 | G26: Partly | H26: Renewal stated in the terms link, not beside the price. | I26: Yes | J26: Partly | K26: Not sure | M26: =IF(G26="","",F26*(2-IF(G26="Yes",2,IF(G26="Partly",1,0)))) -> 3 | N26: =IF(M26="",-1,M26+(29+1-ROW())/1000) -> 3.004 | O26: =COUNTIF(I26:K26,"Yes") -> 1
B27: 19 | C27: Honesty & terms | D27: Cancelling is as simple as signing up; someone who signed up online can cancel online. | E27: ROSCA requires simple mechanisms to stop recurring charges. California’s automatic renewal law requires online cancellation for consumers who accepted online. See Sources. | F27: 3 | G27: Yes | H27: Cancel button in account settings, online. | I27: Partly | J27: No | K27: Yes | M27: =IF(G27="","",F27*(2-IF(G27="Yes",2,IF(G27="Partly",1,0)))) -> 0 | N27: =IF(M27="",-1,M27+(29+1-ROW())/1000) -> 0.003 | O27: =COUNTIF(I27:K27,"Yes") -> 1
B28: 20 | C28: Honesty & terms | D28: Any “was/now” or crossed-out price is one you actually charged, regularly, for a reasonably substantial period. | E28: The FTC’s Guides Against Deceptive Pricing treat a fictitious former price as a false bargain. See Sources. | F28: 2 | G28: Yes | H28: No former-price claims on the page. | I28: Yes | J28: No | K28: Yes | M28: =IF(G28="","",F28*(2-IF(G28="Yes",2,IF(G28="Partly",1,0)))) -> 0 | N28: =IF(M28="",-1,M28+(29+1-ROW())/1000) -> 0.002 | O28: =COUNTIF(I28:K28,"Yes") -> 2
B29: 21 | C29: Honesty & terms | D29: Every figure, logo and customer quote on the page has a source or written permission. | E29: A claim a buyer can disprove, or a logo used without consent, costs more than it earns. | F29: 2 | G29: Partly | H29: “Saves 6 hours a week” has no source we could show. | I29: Yes | J29: Partly | K29: Yes | M29: =IF(G29="","",F29*(2-IF(G29="Yes",2,IF(G29="Partly",1,0)))) -> 2 | N29: =IF(M29="",-1,M29+(29+1-ROW())/1000) -> 2.001 | O29: =COUNTIF(I29:K29,"Yes") -> 2
B31: Scores (share of the weighted points available on the checks you answered)
C32: Area | G32: =G8 -> Fieldnote | I32: =I8 -> Competitor A | J32: =J8 -> Competitor B | K32: =K8 -> Competitor C
C33: Clarity | G33: =IF(2*SUMPRODUCT($F$9:$F$29*($C$9:$C$29="Clarity")*(G9:G29<>""))=0,"",SUMPRODUCT($F$9:$F$29*($C$9:$C$29="Clarity")*((G9:G29="Yes")*2+(G9:G29="Partly")*1))/(2*SUMPRODUCT($F$9:$F$29*($C$9:$C$29="Clarity")*(G9:G29<>"")))) -> 0.46153846 | I33: =IF(2*SUMPRODUCT($F$9:$F$29*($C$9:$C$29="Clarity")*(I9:I29<>""))=0,"",SUMPRODUCT($F$9:$F$29*($C$9:$C$29="Clarity")*((I9:I29="Yes")*2+(I9:I29="Partly")*1))/(2*SUMPRODUCT($F$9:$F$29*($C$9:$C$29="Clarity")*(I9:I29<>"")))) -> 0.92307692 | J33: =IF(2*SUMPRODUCT($F$9:$F$29*($C$9:$C$29="Clarity")*(J9:J29<>""))=0,"",SUMPRODUCT($F$9:$F$29*($C$9:$C$29="Clarity")*((J9:J29="Yes")*2+(J9:J29="Partly")*1))/(2*SUMPRODUCT($F$9:$F$29*($C$9:$C$29="Clarity")*(J9:J29<>"")))) -> 0.42307692 | K33: =IF(2*SUMPRODUCT($F$9:$F$29*($C$9:$C$29="Clarity")*(K9:K29<>""))=0,"",SUMPRODUCT($F$9:$F$29*($C$9:$C$29="Clarity")*((K9:K29="Yes")*2+(K9:K29="Partly")*1))/(2*SUMPRODUCT($F$9:$F$29*($C$9:$C$29="Clarity")*(K9:K29<>"")))) -> 0.46153846
C34: Choice | G34: =IF(2*SUMPRODUCT($F$9:$F$29*($C$9:$C$29="Choice")*(G9:G29<>""))=0,"",SUMPRODUCT($F$9:$F$29*($C$9:$C$29="Choice")*((G9:G29="Yes")*2+(G9:G29="Partly")*1))/(2*SUMPRODUCT($F$9:$F$29*($C$9:$C$29="Choice")*(G9:G29<>"")))) -> 0.64285714 | I34: =IF(2*SUMPRODUCT($F$9:$F$29*($C$9:$C$29="Choice")*(I9:I29<>""))=0,"",SUMPRODUCT($F$9:$F$29*($C$9:$C$29="Choice")*((I9:I29="Yes")*2+(I9:I29="Partly")*1))/(2*SUMPRODUCT($F$9:$F$29*($C$9:$C$29="Choice")*(I9:I29<>"")))) -> 0.85714286 | J34: =IF(2*SUMPRODUCT($F$9:$F$29*($C$9:$C$29="Choice")*(J9:J29<>""))=0,"",SUMPRODUCT($F$9:$F$29*($C$9:$C$29="Choice")*((J9:J29="Yes")*2+(J9:J29="Partly")*1))/(2*SUMPRODUCT($F$9:$F$29*($C$9:$C$29="Choice")*(J9:J29<>"")))) -> 0.57142857 | K34: =IF(2*SUMPRODUCT($F$9:$F$29*($C$9:$C$29="Choice")*(K9:K29<>""))=0,"",SUMPRODUCT($F$9:$F$29*($C$9:$C$29="Choice")*((K9:K29="Yes")*2+(K9:K29="Partly")*1))/(2*SUMPRODUCT($F$9:$F$29*($C$9:$C$29="Choice")*(K9:K29<>"")))) -> 0.71428571
C35: Proof & risk | G35: =IF(2*SUMPRODUCT($F$9:$F$29*($C$9:$C$29="Proof & risk")*(G9:G29<>""))=0,"",SUMPRODUCT($F$9:$F$29*($C$9:$C$29="Proof & risk")*((G9:G29="Yes")*2+(G9:G29="Partly")*1))/(2*SUMPRODUCT($F$9:$F$29*($C$9:$C$29="Proof & risk")*(G9:G29<>"")))) -> 0.28571429 | I35: =IF(2*SUMPRODUCT($F$9:$F$29*($C$9:$C$29="Proof & risk")*(I9:I29<>""))=0,"",SUMPRODUCT($F$9:$F$29*($C$9:$C$29="Proof & risk")*((I9:I29="Yes")*2+(I9:I29="Partly")*1))/(2*SUMPRODUCT($F$9:$F$29*($C$9:$C$29="Proof & risk")*(I9:I29<>"")))) -> 0.85714286 | J35: =IF(2*SUMPRODUCT($F$9:$F$29*($C$9:$C$29="Proof & risk")*(J9:J29<>""))=0,"",SUMPRODUCT($F$9:$F$29*($C$9:$C$29="Proof & risk")*((J9:J29="Yes")*2+(J9:J29="Partly")*1))/(2*SUMPRODUCT($F$9:$F$29*($C$9:$C$29="Proof & risk")*(J9:J29<>"")))) -> 0.35714286 | K35: =IF(2*SUMPRODUCT($F$9:$F$29*($C$9:$C$29="Proof & risk")*(K9:K29<>""))=0,"",SUMPRODUCT($F$9:$F$29*($C$9:$C$29="Proof & risk")*((K9:K29="Yes")*2+(K9:K29="Partly")*1))/(2*SUMPRODUCT($F$9:$F$29*($C$9:$C$29="Proof & risk")*(K9:K29<>"")))) -> 0.28571429
C36: Friction | G36: =IF(2*SUMPRODUCT($F$9:$F$29*($C$9:$C$29="Friction")*(G9:G29<>""))=0,"",SUMPRODUCT($F$9:$F$29*($C$9:$C$29="Friction")*((G9:G29="Yes")*2+(G9:G29="Partly")*1))/(2*SUMPRODUCT($F$9:$F$29*($C$9:$C$29="Friction")*(G9:G29<>"")))) -> 0.6875 | I36: =IF(2*SUMPRODUCT($F$9:$F$29*($C$9:$C$29="Friction")*(I9:I29<>""))=0,"",SUMPRODUCT($F$9:$F$29*($C$9:$C$29="Friction")*((I9:I29="Yes")*2+(I9:I29="Partly")*1))/(2*SUMPRODUCT($F$9:$F$29*($C$9:$C$29="Friction")*(I9:I29<>"")))) -> 1 | J36: =IF(2*SUMPRODUCT($F$9:$F$29*($C$9:$C$29="Friction")*(J9:J29<>""))=0,"",SUMPRODUCT($F$9:$F$29*($C$9:$C$29="Friction")*((J9:J29="Yes")*2+(J9:J29="Partly")*1))/(2*SUMPRODUCT($F$9:$F$29*($C$9:$C$29="Friction")*(J9:J29<>"")))) -> 0.25 | K36: =IF(2*SUMPRODUCT($F$9:$F$29*($C$9:$C$29="Friction")*(K9:K29<>""))=0,"",SUMPRODUCT($F$9:$F$29*($C$9:$C$29="Friction")*((K9:K29="Yes")*2+(K9:K29="Partly")*1))/(2*SUMPRODUCT($F$9:$F$29*($C$9:$C$29="Friction")*(K9:K29<>"")))) -> 0.875
C37: Honesty & terms | G37: =IF(2*SUMPRODUCT($F$9:$F$29*($C$9:$C$29="Honesty & terms")*(G9:G29<>""))=0,"",SUMPRODUCT($F$9:$F$29*($C$9:$C$29="Honesty & terms")*((G9:G29="Yes")*2+(G9:G29="Partly")*1))/(2*SUMPRODUCT($F$9:$F$29*($C$9:$C$29="Honesty & terms")*(G9:G29<>"")))) -> 0.75 | I37: =IF(2*SUMPRODUCT($F$9:$F$29*($C$9:$C$29="Honesty & terms")*(I9:I29<>""))=0,"",SUMPRODUCT($F$9:$F$29*($C$9:$C$29="Honesty & terms")*((I9:I29="Yes")*2+(I9:I29="Partly")*1))/(2*SUMPRODUCT($F$9:$F$29*($C$9:$C$29="Honesty & terms")*(I9:I29<>"")))) -> 0.85 | J37: =IF(2*SUMPRODUCT($F$9:$F$29*($C$9:$C$29="Honesty & terms")*(J9:J29<>""))=0,"",SUMPRODUCT($F$9:$F$29*($C$9:$C$29="Honesty & terms")*((J9:J29="Yes")*2+(J9:J29="Partly")*1))/(2*SUMPRODUCT($F$9:$F$29*($C$9:$C$29="Honesty & terms")*(J9:J29<>"")))) -> 0.25 | K37: =IF(2*SUMPRODUCT($F$9:$F$29*($C$9:$C$29="Honesty & terms")*(K9:K29<>""))=0,"",SUMPRODUCT($F$9:$F$29*($C$9:$C$29="Honesty & terms")*((K9:K29="Yes")*2+(K9:K29="Partly")*1))/(2*SUMPRODUCT($F$9:$F$29*($C$9:$C$29="Honesty & terms")*(K9:K29<>"")))) -> 0.7
C38: Total | G38: =IF(2*SUMPRODUCT($F$9:$F$29*(G9:G29<>""))=0,"",SUMPRODUCT($F$9:$F$29*((G9:G29="Yes")*2+(G9:G29="Partly")*1))/(2*SUMPRODUCT($F$9:$F$29*(G9:G29<>"")))) -> 0.56666667 | I38: =IF(2*SUMPRODUCT($F$9:$F$29*(I9:I29<>""))=0,"",SUMPRODUCT($F$9:$F$29*((I9:I29="Yes")*2+(I9:I29="Partly")*1))/(2*SUMPRODUCT($F$9:$F$29*(I9:I29<>"")))) -> 0.9 | J38: =IF(2*SUMPRODUCT($F$9:$F$29*(J9:J29<>""))=0,"",SUMPRODUCT($F$9:$F$29*((J9:J29="Yes")*2+(J9:J29="Partly")*1))/(2*SUMPRODUCT($F$9:$F$29*(J9:J29<>"")))) -> 0.36666667 | K38: =IF(2*SUMPRODUCT($F$9:$F$29*(K9:K29<>""))=0,"",SUMPRODUCT($F$9:$F$29*((K9:K29="Yes")*2+(K9:K29="Partly")*1))/(2*SUMPRODUCT($F$9:$F$29*(K9:K29<>"")))) -> 0.6
C39: Answered | G39: =COUNTA(G9:G29)&" of 21" -> 21 of 21 | I39: =COUNTA(I9:I29)&" of 21" -> 21 of 21 | J39: =COUNTA(J9:J29)&" of 21" -> 21 of 21 | K39: =COUNTA(K9:K29)&" of 21" -> 21 of 21
C40: “Not sure” | G40: =COUNTIF(G9:G29,"Not sure") -> 1 | I40: =COUNTIF(I9:I29,"Not sure") -> 0 | J40: =COUNTIF(J9:J29,"Not sure") -> 1 | K40: =COUNTIF(K9:K29,"Not sure") -> 2
C41: Every “Not sure” is something to go and check. On your own page it usually means nobody owns that part of it.
B43: Fix these first on your page (weight × points missed; ties go to the earlier check)
B44: # | C44: Area | D44: Check | E44: What you saw | F44: Points missed | G44: Your answer | H44: Competitors that pass
...

Sheet Diagnose - Competitor Grid
A1: AAJ
A2: Diagnose — Competitor Price Grid
A3: The facts of each price list, with the date you captured them. Prices are monthly unless the column says otherwise.
B5: Capture from the live page, on one day, and save a screenshot. The first four names come from the Teardown tab; add more in the rows below. Leave a cell blank rather than guessing.
B7: Company | C7: Pricing page URL | D7: Date captured | E7: Plans | F7: Value metric | G7: Free plan or trial | H7: Entry plan, billed monthly ($/mo) | I7: Entry plan, billed annually ($/mo) | J7: Annual saving (auto) | K7: Top self-serve plan ($/mo) | L7: Where “Contact sales” starts | M7: What they lead with | N7: What they leave out | O7: Entry price vs yours (auto)
B8: ='Diagnose - Teardown'!G8 -> Fieldnote | C8: fieldnote.example/pricing | D8: 46267 | E8: 3 | F8: Per technician | G8: 14-day trial | H8: 29 | I8: 24 | J8: =IF(OR(H8="",I8="",H8=0),"",1-I8/H8) -> 0.17241379 | K8: 149 | L8: Above 25 technicians | M8: Scheduling in one screen | O8: =IF(OR(H8="",$H$8="",$H$8=0),"",H8/$H$8) -> 1
B9: ='Diagnose - Teardown'!I8 -> Competitor A | D9: 46267 | E9: 3 | F9: Per technician | G9: Free plan, 2 users | H9: 25 | I9: 21 | J9: =IF(OR(H9="",I9="",H9=0),"",1-I9/H9) -> 0.16 | K9: 119 | L9: Above 50 technicians | M9: Free plan; payroll add-on | O9: =IF(OR(H9="",$H$8="",$H$8=0),"",H9/$H$8) -> 0.86206897
B10: ='Diagnose - Teardown'!J8 -> Competitor B | D10: 46267 | E10: 4 | F10: Per account | G10: Demo only | J10: =IF(OR(H10="",I10="",H10=0),"",1-I10/H10) | L10: All plans | M10: Enterprise features | O10: =IF(OR(H10="",$H$8="",$H$8=0),"",H10/$H$8)
B11: ='Diagnose - Teardown'!K8 -> Competitor C | D11: 46267 | E11: 2 | F11: Per job booked | G11: 30-day trial | H11: 39 | I11: 33 | J11: =IF(OR(H11="",I11="",H11=0),"",1-I11/H11) -> 0.15384615 | K11: 149 | L11: None shown | M11: Pay for what you book | O11: =IF(OR(H11="",$H$8="",$H$8=0),"",H11/$H$8) -> 1.3448276
J12: =IF(OR(H12="",I12="",H12=0),"",1-I12/H12) | O12: =IF(OR(H12="",$H$8="",$H$8=0),"",H12/$H$8)
J13: =IF(OR(H13="",I13="",H13=0),"",1-I13/H13) | O13: =IF(OR(H13="",$H$8="",$H$8=0),"",H13/$H$8)
J14: =IF(OR(H14="",I14="",H14=0),"",1-I14/H14) | O14: =IF(OR(H14="",$H$8="",$H$8=0),"",H14/$H$8)
J15: =IF(OR(H15="",I15="",H15=0),"",1-I15/H15) | O15: =IF(OR(H15="",$H$8="",$H$8=0),"",H15/$H$8)
B17: “Entry price vs yours” compares entry plans billed monthly: 0.86x means that competitor’s entry plan costs 76% of yours. It is a price comparison, not a value comparison: check that the value metric matches before reading much into it.
B19: What this tells you (write it down while the pages are fresh)
B20: Where do we sit on price against the two competitors buyers mention most?
B21: What does every competitor show that we do not?
B22: What does no competitor show that buyers keep asking sales about?

Sheet Design - Test Plan
A1: AAJ
A2: Design — Price-Test Plan
A3: Work out, before you start, whether a live test can answer the question, and write down how you will decide.
B5: 1 · The test
B6: Test name | C6: Team plan $49 → $59 for new visitors | E6: Short enough to use as the row name in the Test Log.
B7: The change, exactly | C7: Team plan list price from $49 to $59 per technician per month. Nothing else on the page changes. | E7: Change one thing. A new price and a new layout together cannot be told apart afterwards.
B8: Hypothesis | C8: Small contractors choose Team for dispatch, not price, so a higher price will raise revenue per visitor. | E8: [Change] will raise revenue per visitor, because [reason].
B9: Who sees it | C9: New visitors to the pricing page, split at random. Existing customers keep their price. | E9: Never test on existing customers’ bills. See section 6.
B10: What counts as a conversion | C10: First paid invoice on any plan, within 30 days of the visit. | E10: Paid, not trial starts: a price that attracts trials can still lose revenue.
B12: 2 · The numbers (inputs)
B13: Current price, per conversion ($) | C13: 49 | E13: What one conversion is worth today: first month, first year, or average first invoice. Use the same basis for both prices.
B14: Test price, per conversion ($) | C14: 59 | E14: Same basis as the current price.
B15: Conversion today (visitor → paid) | C15: 0.02 | E15: From your own analytics, over at least a month. Fieldnote’s 2.0% is invented.
B16: Your best guess: conversion at the test price | C16: 0.018 | E16: An honest guess. The break-even line below tells you how far it can fall before the test price loses revenue.
B17: Pricing page visitors per week | C17: 3000 | E17: Unique visitors to the pricing page, from your analytics.
B18: Share of those visitors in the test | C18: 1 | E18: Usually 100%, split evenly between the two prices.
B19: Significance level (α) | C19: 0.05 | E19: 0.05 is the convention: a 5% chance of calling a difference that is not there.
B20: Power | C20: 0.8 | E20: 0.80 is the convention: an 80% chance of detecting the difference if it is real.
B21: Weeks you could run it | C21: 8 | E21: Whole weeks, so every day of the week is counted equally. Eight is my rule of thumb for the longest a price test stays clean.
B23: 3 · What the numbers say (auto)
B24: Price change | C24: =IF($C$13=0,"",$C$14/$C$13-1) -> 0.20408163 | E24: Positive is a rise.
B25: Break-even conversion at the test price | C25: =IF($C$14=0,"",$C$15*$C$13/$C$14) -> 0.016610169 | E25: Below this, the test price earns less per visitor than today’s price.
B26: …which is a change in conversion of | C26: =IF($C$14=0,"",$C$13/$C$14-1) -> -0.16949153 | E26: A 20% price rise breaks even if conversion falls by no more than about 17%. The arithmetic is not symmetric.
B27: Revenue per visitor today | C27: =($C$13*$C$15) -> 0.98
B28: Revenue per visitor at the test price (your guess) | C28: =($C$14*$C$16) -> 1.062
B29: Expected change in revenue per visitor | C29: =IF(($C$13*$C$15)=0,"",($C$14*$C$16)/($C$13*$C$15)-1) -> 0.083673469 | E29: If this is negative, your own guess says the test price loses. Test only if you doubt the guess.
B30: Visitors needed in each arm | C30: =IF(ABS(($C$14*$C$16)-($C$13*$C$15))<0.000000001,"no difference to detect",ROUNDUP((NORMSINV(1-$C$19/2)+NORMSINV($C$20))^2*(($C$13^2*$C$15*(1-$C$15))+($C$14^2*$C$16*(1-$C$16)))/(($C$14*$C$16)-($C$13*$C$15))^2,0)) -> 126757 | E30: For a two-sided test on revenue per visitor at your α and power. Method on the Sources tab.
B31: Weeks needed | C31: =IF(ISNUMBER(C30),IF($C$17*$C$18=0,"",ROUNDUP(2*C30/($C$17*$C$18),0)),"") -> 85 | E31: Both arms together, at your weekly traffic, rounded up to whole weeks.
B32: Smallest change you could detect in your weeks | C32: =IF($C$17*$C$18*$C$21=0,"",IF(($C$13*$C$15)=0,"",(NORMSINV(1-$C$19/2)+NORMSINV($C$20))*SQRT(2*($C$13^2*$C$15*(1-$C$15))/($C$17*$C$18*$C$21/2))/($C$13*$C$15))) -> 0.25317817 | E32: Approximate: the change in revenue per visitor your traffic could reliably detect in the weeks you have. Smaller real changes will look like noise.
B33: Verdict | C33: =IF(NOT(ISNUMBER(C30)),"Your two guesses give the same revenue per visitor, so there is nothing for a test to detect. Revisit the guess.",IF(C31<=$C$21,"A live test can answer this in about "&C31&" weeks. Run it to the full planned size, and do not stop early because it looks good.","A live test cannot answer this in "&$C$21&" weeks: it would need about "&TEXT(C31,"#,##0")&". In "&$C$21&" weeks you could only detect a change of about "&TEXT(C32,"0%")&" in revenue per visitor. Use an alternative in section 5.")) -> A live test cannot answer this in 8 weeks: it would need about 85. In 8 weeks you could only detect a change of about 25% in revenue per visitor. Use an alternative in section 5.
B34: Fieldnote’s result is not unusual. With a few thousand pricing-page visitors a week and a conversion rate of a few percent, only large changes in revenue per visitor show up in a live test within a couple of months. The workbook tells you where you stand before you start rather than after.
B36: 4 · Decision rules (written before launch)
B37: Keep the test price if | C37: Revenue per visitor at the test price is higher, with p below α, at the full planned size.
B38: Keep the current price if | C38: Revenue per visitor is lower at the test price, or there is no clear difference at the planned size.
B39: Stop early only if | C39: A guardrail below is breached. Never stop because the result looks good: checking repeatedly and stopping at the first significant reading inflates false positives.
B40: Guardrails | C40: Refunds and cancellations in the first 30 days; discount requests to sales; support tickets about price.
B41: Retention check | C41: Compare 90-day retention of each arm’s customers before making the price permanent.
B42: Read date | C42: [Date, set now]
B43: Owner, and the one approver | C43: [Name] · [Name]
B45: 5 · When a live test cannot answer it
...

Sheet Execute - Test Log
A1: AAJ
A2: Execute — Price-Test Log
A3: One row per test. Write the planned size before launch; read the result against it.
B5: Revenue is what converters actually paid, on the same basis as the price (first month, first year, or first invoice). The p-value compares revenue per visitor and assumes each conversion in an arm is worth about the same; if the arms differ a lot in plan mix, treat it as approximate. For “Before-after” and “Sales quotes”, nothing was randomised, so anything else that changed is mixed into the result.
B7: ID (auto) | C7: Test name | D7: Design | E7: Start | F7: End | G7: Days (auto) | H7: Price A ($) | I7: Price B ($) | J7: Visitors A | K7: Conversions A | L7: Revenue A ($) | M7: Visitors B | N7: Conversions B | O7: Revenue B ($) | P7: Planned visitors per arm | Q7: Conversion A (auto) | R7: Conversion B (auto) | S7: Revenue / visitor A (auto) | T7: Revenue / visitor B (auto) | U7: Change in revenue / visitor (auto) | V7: p-value (auto) | W7: Read-out (auto) | X7: Decision | Y7: Retention check (auto) | Z7: Retained A | AA7: Retained B | AB7: What we learned
B8: =IF(C8="","","T-"&TEXT(ROW()-7,"000")) -> T-001 | C8: Team plan $49 → $59 for new visitors | D8: Live A/B | E8: 46174 | F8: 46215 | G8: =IF(OR(E8="",F8=""),"",F8-E8+1) -> 42 | H8: 49 | I8: 59 | J8: 9000 | K8: 180 | L8: 8820 | M8: 9000 | N8: 171 | O8: 10089 | P8: 126700 | Q8: =IF(OR(J8="",J8=0,K8=""),"",K8/J8) -> 0.02 | R8: =IF(OR(M8="",M8=0,N8=""),"",N8/M8) -> 0.019 | S8: =IF(OR(J8="",J8=0,L8=""),"",L8/J8) -> 0.98 | T8: =IF(OR(M8="",M8=0,O8=""),"",O8/M8) -> 1.121 | U8: =IF(OR(S8="",T8="",S8=0),"",T8/S8-1) -> 0.14387755 | V8: =IF(OR(Q8="",R8="",S8="",T8=""),"",IFERROR(2*(1-NORMSDIST(ABS(T8-S8)/SQRT((L8/K8)^2*Q8*(1-Q8)/J8+(O8/N8)^2*R8*(1-R8)/M8))),"")) -> 0.20612887 | W8: =IF(C8="","",IF(OR(J8="",M8=""),"Enter the results",IF(P8="","Write the plan first: planned visitors per arm",IF(MIN(J8,M8)<P8,"Too early: "&TEXT(MIN(J8,M8)/P8,"0%")&" of the planned size",IF(V8="","Check the inputs",IF(V8<'Design - Test Plan'!$C$19,IF(T8>S8,"B earns more per visitor","A earns more per visitor"),"No clear difference at the planned size"))))&IF(OR(D8="Before-after",D8="Sales quotes")," (not randomised: read as direction)",""))) -> Too early: 7% of the planned size | X8: Undecided | Y8: =IF(F8="","",F8+90) -> 46305 | AB8: Up 14% on revenue per visitor after six weeks, but at 7% of the planned size. Not a result. Moved to a before-after test.
B9: =IF(C9="","","T-"&TEXT(ROW()-7,"000")) -> T-002 | C9: Team plan $59 for all new customers from 1 Aug | D9: Before-after | E9: 46179 | F9: 46291 | G9: =IF(OR(E9="",F9=""),"",F9-E9+1) -> 113 | H9: 49 | I9: 59 | J9: 24000 | K9: 480 | L9: 23520 | M9: 24500 | N9: 441 | O9: 26019 | P9: 22000 | Q9: =IF(OR(J9="",J9=0,K9=""),"",K9/J9) -> 0.02 | R9: =IF(OR(M9="",M9=0,N9=""),"",N9/M9) -> 0.018 | S9: =IF(OR(J9="",J9=0,L9=""),"",L9/J9) -> 0.98 | T9: =IF(OR(M9="",M9=0,O9=""),"",O9/M9) -> 1.062 | U9: =IF(OR(S9="",T9="",S9=0),"",T9/S9-1) -> 0.083673469 | V9: =IF(OR(Q9="",R9="",S9="",T9=""),"",IFERROR(2*(1-NORMSDIST(ABS(T9-S9)/SQRT((L9/K9)^2*Q9*(1-Q9)/J9+(O9/N9)^2*R9*(1-R9)/M9))),"")) -> 0.22013465 | W9: =IF(C9="","",IF(OR(J9="",M9=""),"Enter the results",IF(P9="","Write the plan first: planned visitors per arm",IF(MIN(J9,M9)<P9,"Too early: "&TEXT(MIN(J9,M9)/P9,"0%")&" of the planned size",IF(V9="","Check the inputs",IF(V9<'Design - Test Plan'!$C$19,IF(T9>S9,"B earns more per visitor","A earns more per visitor"),"No clear difference at the planned size"))))&IF(OR(D9="Before-after",D9="Sales quotes")," (not randomised: read as direction)",""))) -> No clear difference at the planned size (not randomised: read as direction) | X9: Keep B | Y9: =IF(F9="","",F9+90) -> 46381 | AB9: Rule written before the change: keep $59 unless revenue per visitor falls or 90-day retention drops. Neither has so far. Two campaigns ran in the after period, so the 8% is direction, not proof. Before: 6 Jun–31 Jul; after: 1 Aug–26 Sep.
B10: =IF(C10="","","T-"&TEXT(ROW()-7,"000")) | G10: =IF(OR(E10="",F10=""),"",F10-E10+1) | Q10: =IF(OR(J10="",J10=0,K10=""),"",K10/J10) | R10: =IF(OR(M10="",M10=0,N10=""),"",N10/M10) | S10: =IF(OR(J10="",J10=0,L10=""),"",L10/J10) | T10: =IF(OR(M10="",M10=0,O10=""),"",O10/M10) | U10: =IF(OR(S10="",T10="",S10=0),"",T10/S10-1) | V10: =IF(OR(Q10="",R10="",S10="",T10=""),"",IFERROR(2*(1-NORMSDIST(ABS(T10-S10)/SQRT((L10/K10)^2*Q10*(1-Q10)/J10+(O10/N10)^2*R10*(1-R10)/M10))),"")) | W10: =IF(C10="","",IF(OR(J10="",M10=""),"Enter the results",IF(P10="","Write the plan first: planned visitors per arm",IF(MIN(J10,M10)<P10,"Too early: "&TEXT(MIN(J10,M10)/P10,"0%")&" of the planned size",IF(V10="","Check the inputs",IF(V10<'Design - Test Plan'!$C$19,IF(T10>S10,"B earns more per visitor","A earns more per visitor"),"No clear difference at the planned size"))))&IF(OR(D10="Before-after",D10="Sales quotes")," (not randomised: read as direction)",""))) | Y10: =IF(F10="","",F10+90)
B11: =IF(C11="","","T-"&TEXT(ROW()-7,"000")) | G11: =IF(OR(E11="",F11=""),"",F11-E11+1) | Q11: =IF(OR(J11="",J11=0,K11=""),"",K11/J11) | R11: =IF(OR(M11="",M11=0,N11=""),"",N11/M11) | S11: =IF(OR(J11="",J11=0,L11=""),"",L11/J11) | T11: =IF(OR(M11="",M11=0,O11=""),"",O11/M11) | U11: =IF(OR(S11="",T11="",S11=0),"",T11/S11-1) | V11: =IF(OR(Q11="",R11="",S11="",T11=""),"",IFERROR(2*(1-NORMSDIST(ABS(T11-S11)/SQRT((L11/K11)^2*Q11*(1-Q11)/J11+(O11/N11)^2*R11*(1-R11)/M11))),"")) | W11: =IF(C11="","",IF(OR(J11="",M11=""),"Enter the results",IF(P11="","Write the plan first: planned visitors per arm",IF(MIN(J11,M11)<P11,"Too early: "&TEXT(MIN(J11,M11)/P11,"0%")&" of the planned size",IF(V11="","Check the inputs",IF(V11<'Design - Test Plan'!$C$19,IF(T11>S11,"B earns more per visitor","A earns more per visitor"),"No clear difference at the planned size"))))&IF(OR(D11="Before-after",D11="Sales quotes")," (not randomised: read as direction)",""))) | Y11: =IF(F11="","",F11+90)
B12: =IF(C12="","","T-"&TEXT(ROW()-7,"000")) | G12: =IF(OR(E12="",F12=""),"",F12-E12+1) | Q12: =IF(OR(J12="",J12=0,K12=""),"",K12/J12) | R12: =IF(OR(M12="",M12=0,N12=""),"",N12/M12) | S12: =IF(OR(J12="",J12=0,L12=""),"",L12/J12) | T12: =IF(OR(M12="",M12=0,O12=""),"",O12/M12) | U12: =IF(OR(S12="",T12="",S12=0),"",T12/S12-1) | V12: =IF(OR(Q12="",R12="",S12="",T12=""),"",IFERROR(2*(1-NORMSDIST(ABS(T12-S12)/SQRT((L12/K12)^2*Q12*(1-Q12)/J12+(O12/N12)^2*R12*(1-R12)/M12))),"")) | W12: =IF(C12="","",IF(OR(J12="",M12=""),"Enter the results",IF(P12="","Write the plan first: planned visitors per arm",IF(MIN(J12,M12)<P12,"Too early: "&TEXT(MIN(J12,M12)/P12,"0%")&" of the planned size",IF(V12="","Check the inputs",IF(V12<'Design - Test Plan'!$C$19,IF(T12>S12,"B earns more per visitor","A earns more per visitor"),"No clear difference at the planned size"))))&IF(OR(D12="Before-after",D12="Sales quotes")," (not randomised: read as direction)",""))) | Y12: =IF(F12="","",F12+90)
B13: =IF(C13="","","T-"&TEXT(ROW()-7,"000")) | G13: =IF(OR(E13="",F13=""),"",F13-E13+1) | Q13: =IF(OR(J13="",J13=0,K13=""),"",K13/J13) | R13: =IF(OR(M13="",M13=0,N13=""),"",N13/M13) | S13: =IF(OR(J13="",J13=0,L13=""),"",L13/J13) | T13: =IF(OR(M13="",M13=0,O13=""),"",O13/M13) | U13: =IF(OR(S13="",T13="",S13=0),"",T13/S13-1) | V13: =IF(OR(Q13="",R13="",S13="",T13=""),"",IFERROR(2*(1-NORMSDIST(ABS(T13-S13)/SQRT((L13/K13)^2*Q13*(1-Q13)/J13+(O13/N13)^2*R13*(1-R13)/M13))),"")) | W13: =IF(C13="","",IF(OR(J13="",M13=""),"Enter the results",IF(P13="","Write the plan first: planned visitors per arm",IF(MIN(J13,M13)<P13,"Too early: "&TEXT(MIN(J13,M13)/P13,"0%")&" of the planned size",IF(V13="","Check the inputs",IF(V13<'Design - Test Plan'!$C$19,IF(T13>S13,"B earns more per visitor","A earns more per visitor"),"No clear difference at the planned size"))))&IF(OR(D13="Before-after",D13="Sales quotes")," (not randomised: read as direction)",""))) | Y13: =IF(F13="","",F13+90)
B14: =IF(C14="","","T-"&TEXT(ROW()-7,"000")) | G14: =IF(OR(E14="",F14=""),"",F14-E14+1) | Q14: =IF(OR(J14="",J14=0,K14=""),"",K14/J14) | R14: =IF(OR(M14="",M14=0,N14=""),"",N14/M14) | S14: =IF(OR(J14="",J14=0,L14=""),"",L14/J14) | T14: =IF(OR(M14="",M14=0,O14=""),"",O14/M14) | U14: =IF(OR(S14="",T14="",S14=0),"",T14/S14-1) | V14: =IF(OR(Q14="",R14="",S14="",T14=""),"",IFERROR(2*(1-NORMSDIST(ABS(T14-S14)/SQRT((L14/K14)^2*Q14*(1-Q14)/J14+(O14/N14)^2*R14*(1-R14)/M14))),"")) | W14: =IF(C14="","",IF(OR(J14="",M14=""),"Enter the results",IF(P14="","Write the plan first: planned visitors per arm",IF(MIN(J14,M14)<P14,"Too early: "&TEXT(MIN(J14,M14)/P14,"0%")&" of the planned size",IF(V14="","Check the inputs",IF(V14<'Design - Test Plan'!$C$19,IF(T14>S14,"B earns more per visitor","A earns more per visitor"),"No clear difference at the planned size"))))&IF(OR(D14="Before-after",D14="Sales quotes")," (not randomised: read as direction)",""))) | Y14: =IF(F14="","",F14+90)
B15: =IF(C15="","","T-"&TEXT(ROW()-7,"000")) | G15: =IF(OR(E15="",F15=""),"",F15-E15+1) | Q15: =IF(OR(J15="",J15=0,K15=""),"",K15/J15) | R15: =IF(OR(M15="",M15=0,N15=""),"",N15/M15) | S15: =IF(OR(J15="",J15=0,L15=""),"",L15/J15) | T15: =IF(OR(M15="",M15=0,O15=""),"",O15/M15) | U15: =IF(OR(S15="",T15="",S15=0),"",T15/S15-1) | V15: =IF(OR(Q15="",R15="",S15="",T15=""),"",IFERROR(2*(1-NORMSDIST(ABS(T15-S15)/SQRT((L15/K15)^2*Q15*(1-Q15)/J15+(O15/N15)^2*R15*(1-R15)/M15))),"")) | W15: =IF(C15="","",IF(OR(J15="",M15=""),"Enter the results",IF(P15="","Write the plan first: planned visitors per arm",IF(MIN(J15,M15)<P15,"Too early: "&TEXT(MIN(J15,M15)/P15,"0%")&" of the planned size",IF(V15="","Check the inputs",IF(V15<'Design - Test Plan'!$C$19,IF(T15>S15,"B earns more per visitor","A earns more per visitor"),"No clear difference at the planned size"))))&IF(OR(D15="Before-after",D15="Sales quotes")," (not randomised: read as direction)",""))) | Y15: =IF(F15="","",F15+90)
B16: =IF(C16="","","T-"&TEXT(ROW()-7,"000")) | G16: =IF(OR(E16="",F16=""),"",F16-E16+1) | Q16: =IF(OR(J16="",J16=0,K16=""),"",K16/J16) | R16: =IF(OR(M16="",M16=0,N16=""),"",N16/M16) | S16: =IF(OR(J16="",J16=0,L16=""),"",L16/J16) | T16: =IF(OR(M16="",M16=0,O16=""),"",O16/M16) | U16: =IF(OR(S16="",T16="",S16=0),"",T16/S16-1) | V16: =IF(OR(Q16="",R16="",S16="",T16=""),"",IFERROR(2*(1-NORMSDIST(ABS(T16-S16)/SQRT((L16/K16)^2*Q16*(1-Q16)/J16+(O16/N16)^2*R16*(1-R16)/M16))),"")) | W16: =IF(C16="","",IF(OR(J16="",M16=""),"Enter the results",IF(P16="","Write the plan first: planned visitors per arm",IF(MIN(J16,M16)<P16,"Too early: "&TEXT(MIN(J16,M16)/P16,"0%")&" of the planned size",IF(V16="","Check the inputs",IF(V16<'Design - Test Plan'!$C$19,IF(T16>S16,"B earns more per visitor","A earns more per visitor"),"No clear difference at the planned size"))))&IF(OR(D16="Before-after",D16="Sales quotes")," (not randomised: read as direction)",""))) | Y16: =IF(F16="","",F16+90)
B17: =IF(C17="","","T-"&TEXT(ROW()-7,"000")) | G17: =IF(OR(E17="",F17=""),"",F17-E17+1) | Q17: =IF(OR(J17="",J17=0,K17=""),"",K17/J17) | R17: =IF(OR(M17="",M17=0,N17=""),"",N17/M17) | S17: =IF(OR(J17="",J17=0,L17=""),"",L17/J17) | T17: =IF(OR(M17="",M17=0,O17=""),"",O17/M17) | U17: =IF(OR(S17="",T17="",S17=0),"",T17/S17-1) | V17: =IF(OR(Q17="",R17="",S17="",T17=""),"",IFERROR(2*(1-NORMSDIST(ABS(T17-S17)/SQRT((L17/K17)^2*Q17*(1-Q17)/J17+(O17/N17)^2*R17*(1-R17)/M17))),"")) | W17: =IF(C17="","",IF(OR(J17="",M17=""),"Enter the results",IF(P17="","Write the plan first: planned visitors per arm",IF(MIN(J17,M17)<P17,"Too early: "&TEXT(MIN(J17,M17)/P17,"0%")&" of the planned size",IF(V17="","Check the inputs",IF(V17<'Design - Test Plan'!$C$19,IF(T17>S17,"B earns more per visitor","A earns more per visitor"),"No clear difference at the planned size"))))&IF(OR(D17="Before-after",D17="Sales quotes")," (not randomised: read as direction)",""))) | Y17: =IF(F17="","",F17+90)
B18: =IF(C18="","","T-"&TEXT(ROW()-7,"000")) | G18: =IF(OR(E18="",F18=""),"",F18-E18+1) | Q18: =IF(OR(J18="",J18=0,K18=""),"",K18/J18) | R18: =IF(OR(M18="",M18=0,N18=""),"",N18/M18) | S18: =IF(OR(J18="",J18=0,L18=""),"",L18/J18) | T18: =IF(OR(M18="",M18=0,O18=""),"",O18/M18) | U18: =IF(OR(S18="",T18="",S18=0),"",T18/S18-1) | V18: =IF(OR(Q18="",R18="",S18="",T18=""),"",IFERROR(2*(1-NORMSDIST(ABS(T18-S18)/SQRT((L18/K18)^2*Q18*(1-Q18)/J18+(O18/N18)^2*R18*(1-R18)/M18))),"")) | W18: =IF(C18="","",IF(OR(J18="",M18=""),"Enter the results",IF(P18="","Write the plan first: planned visitors per arm",IF(MIN(J18,M18)<P18,"Too early: "&TEXT(MIN(J18,M18)/P18,"0%")&" of the planned size",IF(V18="","Check the inputs",IF(V18<'Design - Test Plan'!$C$19,IF(T18>S18,"B earns more per visitor","A earns more per visitor"),"No clear difference at the planned size"))))&IF(OR(D18="Before-after",D18="Sales quotes")," (not randomised: read as direction)",""))) | Y18: =IF(F18="","",F18+90)
B19: =IF(C19="","","T-"&TEXT(ROW()-7,"000")) | G19: =IF(OR(E19="",F19=""),"",F19-E19+1) | Q19: =IF(OR(J19="",J19=0,K19=""),"",K19/J19) | R19: =IF(OR(M19="",M19=0,N19=""),"",N19/M19) | S19: =IF(OR(J19="",J19=0,L19=""),"",L19/J19) | T19: =IF(OR(M19="",M19=0,O19=""),"",O19/M19) | U19: =IF(OR(S19="",T19="",S19=0),"",T19/S19-1) | V19: =IF(OR(Q19="",R19="",S19="",T19=""),"",IFERROR(2*(1-NORMSDIST(ABS(T19-S19)/SQRT((L19/K19)^2*Q19*(1-Q19)/J19+(O19/N19)^2*R19*(1-R19)/M19))),"")) | W19: =IF(C19="","",IF(OR(J19="",M19=""),"Enter the results",IF(P19="","Write the plan first: planned visitors per arm",IF(MIN(J19,M19)<P19,"Too early: "&TEXT(MIN(J19,M19)/P19,"0%")&" of the planned size",IF(V19="","Check the inputs",IF(V19<'Design - Test Plan'!$C$19,IF(T19>S19,"B earns more per visitor","A earns more per visitor"),"No clear difference at the planned size"))))&IF(OR(D19="Before-after",D19="Sales quotes")," (not randomised: read as direction)",""))) | Y19: =IF(F19="","",F19+90)
B20: =IF(C20="","","T-"&TEXT(ROW()-7,"000")) | G20: =IF(OR(E20="",F20=""),"",F20-E20+1) | Q20: =IF(OR(J20="",J20=0,K20=""),"",K20/J20) | R20: =IF(OR(M20="",M20=0,N20=""),"",N20/M20) | S20: =IF(OR(J20="",J20=0,L20=""),"",L20/J20) | T20: =IF(OR(M20="",M20=0,O20=""),"",O20/M20) | U20: =IF(OR(S20="",T20="",S20=0),"",T20/S20-1) | V20: =IF(OR(Q20="",R20="",S20="",T20=""),"",IFERROR(2*(1-NORMSDIST(ABS(T20-S20)/SQRT((L20/K20)^2*Q20*(1-Q20)/J20+(O20/N20)^2*R20*(1-R20)/M20))),"")) | W20: =IF(C20="","",IF(OR(J20="",M20=""),"Enter the results",IF(P20="","Write the plan first: planned visitors per arm",IF(MIN(J20,M20)<P20,"Too early: "&TEXT(MIN(J20,M20)/P20,"0%")&" of the planned size",IF(V20="","Check the inputs",IF(V20<'Design - Test Plan'!$C$19,IF(T20>S20,"B earns more per visitor","A earns more per visitor"),"No clear difference at the planned size"))))&IF(OR(D20="Before-after",D20="Sales quotes")," (not randomised: read as direction)",""))) | Y20: =IF(F20="","",F20+90)
B21: =IF(C21="","","T-"&TEXT(ROW()-7,"000")) | G21: =IF(OR(E21="",F21=""),"",F21-E21+1) | Q21: =IF(OR(J21="",J21=0,K21=""),"",K21/J21) | R21: =IF(OR(M21="",M21=0,N21=""),"",N21/M21) | S21: =IF(OR(J21="",J21=0,L21=""),"",L21/J21) | T21: =IF(OR(M21="",M21=0,O21=""),"",O21/M21) | U21: =IF(OR(S21="",T21="",S21=0),"",T21/S21-1) | V21: =IF(OR(Q21="",R21="",S21="",T21=""),"",IFERROR(2*(1-NORMSDIST(ABS(T21-S21)/SQRT((L21/K21)^2*Q21*(1-Q21)/J21+(O21/N21)^2*R21*(1-R21)/M21))),"")) | W21: =IF(C21="","",IF(OR(J21="",M21=""),"Enter the results",IF(P21="","Write the plan first: planned visitors per arm",IF(MIN(J21,M21)<P21,"Too early: "&TEXT(MIN(J21,M21)/P21,"0%")&" of the planned size",IF(V21="","Check the inputs",IF(V21<'Design - Test Plan'!$C$19,IF(T21>S21,"B earns more per visitor","A earns more per visitor"),"No clear difference at the planned size"))))&IF(OR(D21="Before-after",D21="Sales quotes")," (not randomised: read as direction)",""))) | Y21: =IF(F21="","",F21+90)
... B37: =IF(C37="","","T-"&TEXT(ROW()-7,"000")) | G37: =IF(OR(E37="",F37=""),"",F37-E37+1) | Q37: =IF(OR(J37="",J37=0,K37=""),"",K37/J37) | R37: =IF(OR(M37="",M37=0,N37=""),"",N37/M37) | S37: =IF(OR(J37="",J37=0,L37=""),"",L37/J37) | T37: =IF(OR(M37="",M37=0,O37=""),"",O37/M37) | U37: =IF(OR(S37="",T37="",S37=0),"",T37/S37-1) | V37: =IF(OR(Q37="",R37="",S37="",T37=""),"",IFERROR(2*(1-NORMSDIST(ABS(T37-S37)/SQRT((L37/K37)^2*Q37*(1-Q37)/J37+(O37/N37)^2*R37*(1-R37)/M37))),"")) | W37: =IF(C37="","",IF(OR(J37="",M37=""),"Enter the results",IF(P37="","Write the plan first: planned visitors per arm",IF(MIN(J37,M37)<P37,"Too early: "&TEXT(MIN(J37,M37)/P37,"0%")&" of the planned size",IF(V37="","Check the inputs",IF(V37<'Design - Test Plan'!$C$19,IF(T37>S37,"B earns more per visitor","A earns more per visitor"),"No clear difference at the planned size"))))&IF(OR(D37="Before-after",D37="Sales quotes")," (not randomised: read as direction)",""))) | Y37: =IF(F37="","",F37+90)
B39: Retention check: 90 days after the end date by default. Enter the share of each arm’s new customers still paying on that date. A price that converts well but churns faster has not won yet.

Sheet Sources & Method
A1: AAJ
A2: Sources & Method
A3: Where each rule and formula comes from. Checked September 2026.
B6: Method
B7: Break-even conversion | C7: Arithmetic: revenue per visitor is price × conversion, so the test price breaks even when conversion × price is unchanged. Break-even conversion = today’s conversion × current price ÷ test price.
B8: Visitors needed per arm | C8: n = (z₁₋α/₂ + z₁₋β)² × (σ²A + σ²B) ÷ Δ², where Δ is the expected difference in revenue per visitor and σ² = price² × p × (1 − p) is the variance of revenue per visitor when each conversion is worth the price. The (z + z)² form is the standard sample-size formula for a two-sided test: NIST/SEMATECH e-Handbook of Statistical Methods, 7.2.2.2 “Sample sizes required”, https://www.itl.nist.gov/div898/handbook/prc/section2/prc222.htm
B9: p-value in the Test Log | C9: Two-sample z-test on the difference in revenue per visitor, using the same variance, with each arm’s average revenue per conversion as the price. Two-sided. See The Book of Statistical Proofs, “Two-sample z-test for independent observations”, https://statproofbook.github.io/P/ugkv-ztest2.html
B10: Smallest detectable change | C10: The same formula solved for Δ, using today’s variance for both arms. It is an approximation, shown to help decide whether a test is worth starting.
B11: Why not stop early | C11: Evan Miller, “How Not To Run An A/B Test”: checking a running test repeatedly and stopping when it first looks significant makes a nominal 5% false-positive rate far higher. His advice is to decide the sample size in advance. https://www.evanmiller.org/how-not-to-run-an-ab-test.html
B12: Rules
B13: ROSCA (US) | C13: 15 U.S.C. § 8403: for negative option (recurring) charges online, the seller must clearly and conspicuously disclose all material terms before obtaining billing information, obtain express informed consent before charging, and provide simple mechanisms to stop recurring charges. https://www.law.cornell.edu/uscode/text/15/8403
B14: FTC click-to-cancel status | C14: The FTC’s 2024 amendments to the Negative Option Rule were vacated by the US Court of Appeals for the Eighth Circuit in July 2025. The FTC published an advance notice of proposed rulemaking on 13 March 2026. No replacement rule was in force when this workbook was checked. https://www.ftc.gov/legal-library/browse/rules/negative-option-rule
B15: California automatic renewal law | C15: Cal. Bus. & Prof. Code § 17602: notice no less than 7 and no more than 30 days before a change in the amount charged takes effect (for contracts entered, amended or extended on or after 1 July 2025), and online termination for consumers who accepted online, § 17602(d)(1). “Consumer” means an individual buying for personal, family or household purposes, § 17601. https://law.justia.com/codes/california/code-bpc/division-7/part-3/chapter-1/article-9/section-17602/
B16: Former-price comparisons | C16: FTC Guides Against Deceptive Pricing, 16 CFR § 233.1: a former price supports a comparison only if it is the actual, bona fide price at which the item was offered to the public on a regular basis for a reasonably substantial period of time. https://www.ecfr.gov/current/title-16/chapter-I/subchapter-B/part-233/section-233.1
B17: What is mine, not a source
B18: Judgement | C18: The 21 checks and their weights, the eight-week rule of thumb, the 90-day retention check and the alternatives in section 5 of the Test Plan are my practice from reviewing pricing pages. They are not benchmarks, and nothing in this workbook claims a conversion effect for any of them.
B19: Not legal advice | C19: I am not a lawyer. The rules above are summaries to start from; check them with counsel for where you sell.
B21: AAJ · aajconsult.com · Saroj Jha · saroj@aajconsult.com
